Number of training graphs: 1479
Number of test graphs: 370
Expected all tensors to be on the same device, but found at least two devices, cuda:0 and cpu! (when checking argument for argument mat1 in method wrapper_addmm)
Python 3.10.4 (main, Mar 31 2022, 08:41:55) [GCC 7.5.0]
Type 'copyright', 'credits' or 'license' for more information
IPython 8.5.0 -- An enhanced Interactive Python. Type '?' for help.
RuntimeError('Expected all tensors to be on the same device, but found at least two devices, cuda:0 and cpu! (when checking argument for argument mat1 in method wrapper_addmm)')
---------------------------------------------------------------------------
RuntimeError                              Traceback (most recent call last)
File ~/logical-fallacy-identification/AMR_parsers_and_graphs/gcn.py:56, in NormalNet.forward(self, data, batch)
     54 edge_attr = edge_attr.type(torch.FloatTensor)
---> 56 x = self.conv1(x, edge_index, edge_attr)
     58 x = F.relu(x)
File ~/anaconda3/envs/general/lib/python3.10/site-packages/torch/nn/modules/module.py:1110, in Module._call_impl(self, *input, **kwargs)
   1108 if not (self._backward_hooks or self._forward_hooks or self._forward_pre_hooks or _global_backward_hooks
   1109         or _global_forward_hooks or _global_forward_pre_hooks):
-> 1110     return forward_call(*input, **kwargs)
   1111 # Do not call functions when jit is used
File ~/anaconda3/envs/general/lib/python3.10/site-packages/torch_geometric/nn/conv/transformer_conv.py:171, in TransformerConv.forward(self, x, edge_index, edge_attr, return_attention_weights)
    169     x: PairTensor = (x, x)
--> 171 query = self.lin_query(x[1]).view(-1, H, C)
    172 key = self.lin_key(x[0]).view(-1, H, C)
File ~/anaconda3/envs/general/lib/python3.10/site-packages/torch/nn/modules/module.py:1110, in Module._call_impl(self, *input, **kwargs)
   1108 if not (self._backward_hooks or self._forward_hooks or self._forward_pre_hooks or _global_backward_hooks
   1109         or _global_forward_hooks or _global_forward_pre_hooks):
-> 1110     return forward_call(*input, **kwargs)
   1111 # Do not call functions when jit is used
File ~/anaconda3/envs/general/lib/python3.10/site-packages/torch_geometric/nn/dense/linear.py:118, in Linear.forward(self, x)
    114 r"""
    115 Args:
    116     x (Tensor): The features.
    117 """
--> 118 return F.linear(x, self.weight, self.bias)
RuntimeError: Expected all tensors to be on the same device, but found at least two devices, cuda:0 and cpu! (when checking argument for argument mat1 in method wrapper_addmm)
During handling of the above exception, another exception occurred:
TypeError                                 Traceback (most recent call last)
Cell In [2], line 1
----> 1 x.device()
TypeError: 'torch.device' object is not callable
---------------------------------------------------------------------------
RuntimeError                              Traceback (most recent call last)
File ~/logical-fallacy-identification/AMR_parsers_and_graphs/gcn.py:56, in NormalNet.forward(self, data, batch)
     54 edge_attr = edge_attr.type(torch.FloatTensor)
---> 56 x = self.conv1(x, edge_index, edge_attr)
     58 x = F.relu(x)
File ~/anaconda3/envs/general/lib/python3.10/site-packages/torch/nn/modules/module.py:1110, in Module._call_impl(self, *input, **kwargs)
   1108 if not (self._backward_hooks or self._forward_hooks or self._forward_pre_hooks or _global_backward_hooks
   1109         or _global_forward_hooks or _global_forward_pre_hooks):
-> 1110     return forward_call(*input, **kwargs)
   1111 # Do not call functions when jit is used
File ~/anaconda3/envs/general/lib/python3.10/site-packages/torch_geometric/nn/conv/transformer_conv.py:171, in TransformerConv.forward(self, x, edge_index, edge_attr, return_attention_weights)
    169     x: PairTensor = (x, x)
--> 171 query = self.lin_query(x[1]).view(-1, H, C)
    172 key = self.lin_key(x[0]).view(-1, H, C)
File ~/anaconda3/envs/general/lib/python3.10/site-packages/torch/nn/modules/module.py:1110, in Module._call_impl(self, *input, **kwargs)
   1108 if not (self._backward_hooks or self._forward_hooks or self._forward_pre_hooks or _global_backward_hooks
   1109         or _global_forward_hooks or _global_forward_pre_hooks):
-> 1110     return forward_call(*input, **kwargs)
   1111 # Do not call functions when jit is used
File ~/anaconda3/envs/general/lib/python3.10/site-packages/torch_geometric/nn/dense/linear.py:118, in Linear.forward(self, x)
    114 r"""
    115 Args:
    116     x (Tensor): The features.
    117 """
--> 118 return F.linear(x, self.weight, self.bias)
RuntimeError: Expected all tensors to be on the same device, but found at least two devices, cuda:0 and cpu! (when checking argument for argument mat1 in method wrapper_addmm)
During handling of the above exception, another exception occurred:
AttributeError                            Traceback (most recent call last)
Cell In [3], line 1
----> 1 x.deivce
AttributeError: 'Tensor' object has no attribute 'deivce'
