

















Traceback (most recent call last):
  File "/nas/home/souratih/anaconda3/envs/cbr/lib/python3.9/site-packages/requests/models.py", line 971, in json
    return complexjson.loads(self.text, **kwargs)
  File "/nas/home/souratih/anaconda3/envs/cbr/lib/python3.9/json/__init__.py", line 346, in loads
    return _default_decoder.decode(s)
  File "/nas/home/souratih/anaconda3/envs/cbr/lib/python3.9/json/decoder.py", line 337, in decode
    obj, end = self.raw_decode(s, idx=_w(s, 0).end())
  File "/nas/home/souratih/anaconda3/envs/cbr/lib/python3.9/json/decoder.py", line 355, in raw_decode
    raise JSONDecodeError("Expecting value", s, err.value) from None
json.decoder.JSONDecodeError: Expecting value: line 1 column 1 (char 0)
During handling of the above exception, another exception occurred:
Traceback (most recent call last):
  File "/nas/home/souratih/logical-fallacy-identification/AMR_parsers_and_graphs/conceptnet_augmentation.py", line 88, in <module>
    for new_edge in get_relations_between_words(node1_label, node2_label):
  File "/nas/home/souratih/logical-fallacy-identification/AMR_parsers_and_graphs/conceptnet_augmentation.py", line 39, in get_relations_between_words
    obj = make_request(query=query)
  File "/nas/home/souratih/logical-fallacy-identification/AMR_parsers_and_graphs/conceptnet_augmentation.py", line 25, in make_request
    return response.json()
  File "/nas/home/souratih/anaconda3/envs/cbr/lib/python3.9/site-packages/requests/models.py", line 975, in json
    raise RequestsJSONDecodeError(e.msg, e.doc, e.pos)
requests.exceptions.JSONDecodeError: Expecting value: line 1 column 1 (char 0)