Some weights of the model checkpoint at bert-base-uncased were not used when initializing BertModel: ['cls.predictions.decoder.weight', 'cls.seq_relationship.weight', 'cls.seq_relationship.bias', 'cls.predictions.transform.dense.bias', 'cls.predictions.bias', 'cls.predictions.transform.LayerNorm.weight', 'cls.predictions.transform.dense.weight', 'cls.predictions.transform.LayerNorm.bias']
- This IS expected if you are initializing BertModel from the checkpoint of a model trained on another task or with another architecture (e.g. initializing a BertForSequenceClassification model from a BertForPreTraining model).
- This IS NOT expected if you are initializing BertModel from the checkpoint of a model that you expect to be exactly identical (initializing a BertForSequenceClassification model from a BertForSequenceClassification model).
Traceback (most recent call last):
  File "/cluster/raid/home/zhivar.sourati/logical-fallacy-identification/AMR_parsers_and_graphs/gcn.py", line 236, in <module>
    dataset = Logical_Fallacy_Dataset(path_to_dataset=args.train_input_file)
  File "/cluster/raid/home/zhivar.sourati/logical-fallacy-identification/AMR_parsers_and_graphs/gcn.py", line 113, in __init__
    super().__init__()
  File "/cluster/raid/home/zhivar.sourati/anaconda3/envs/general/lib/python3.10/site-packages/torch_geometric/data/in_memory_dataset.py", line 50, in __init__
    super().__init__(root, transform, pre_transform, pre_filter)
  File "/cluster/raid/home/zhivar.sourati/anaconda3/envs/general/lib/python3.10/site-packages/torch_geometric/data/dataset.py", line 87, in __init__
    self._process()
  File "/cluster/raid/home/zhivar.sourati/anaconda3/envs/general/lib/python3.10/site-packages/torch_geometric/data/dataset.py", line 148, in _process
    f = osp.join(self.processed_dir, 'pre_transform.pt')
  File "/cluster/raid/home/zhivar.sourati/anaconda3/envs/general/lib/python3.10/site-packages/torch_geometric/data/dataset.py", line 98, in processed_dir
    return osp.join(self.root, 'processed')
  File "/cluster/raid/home/zhivar.sourati/anaconda3/envs/general/lib/python3.10/posixpath.py", line 76, in join
    a = os.fspath(a)
TypeError: expected str, bytes or os.PathLike object, not NoneType
